<?xml version="1.0"?>
<robot name="ackermann_car" xmlns:xacro="http://www.ros.org/wiki/xacro">

  <xacro:arg name="use_ros2_control" default="false"/>
  <xacro:arg name="control_config" default=""/>

  <!-- ===================== -->
  <!-- Parameters -->
  <!-- ===================== -->
  <xacro:property name="base_length" value="0.60"/>
  <xacro:property name="base_width"  value="0.32"/>
  <xacro:property name="base_height" value="0.12"/>
  <xacro:property name="base_mass"   value="5.0"/>

  <xacro:property name="wheel_radius" value="0.07"/>
  <xacro:property name="wheel_width"  value="0.04"/>
  <xacro:property name="wheel_mass"   value="0.25"/>

  <xacro:property name="steer_link_radius" value="0.025"/>
  <xacro:property name="steer_link_length" value="0.04"/>
  <xacro:property name="steer_link_mass"   value="0.10"/>

  <xacro:property name="front_x" value="0.22"/>
  <xacro:property name="rear_x"  value="-0.22"/>
  <xacro:property name="left_y"  value="0.19"/>
  <xacro:property name="right_y" value="-0.19"/>

  <!-- ===================== -->
  <!-- Materials -->
  <!-- ===================== -->
  <material name="blue">
    <color rgba="0.1 0.2 0.8 1.0"/>
  </material>

  <material name="black">
    <color rgba="0.02 0.02 0.02 1.0"/>
  </material>

  <material name="gray">
    <color rgba="0.5 0.5 0.5 1.0"/>
  </material>

  <material name="red">
    <color rgba="0.8 0.1 0.1 1.0"/>
  </material>

  <!-- ===================== -->
  <!-- Inertia Macros -->
  <!-- ===================== -->
  <xacro:macro name="box_inertia" params="m x y z">
    <inertial>
      <origin xyz="0 0 0" rpy="0 0 0"/>
      <mass value="${m}"/>
      <inertia
        ixx="${m / 12.0 * (y * y + z * z)}"
        ixy="0.0"
        ixz="0.0"
        iyy="${m / 12.0 * (x * x + z * z)}"
        iyz="0.0"
        izz="${m / 12.0 * (x * x + y * y)}"/>
    </inertial>
  </xacro:macro>

  <!-- wheel axis is Y -->
  <xacro:macro name="wheel_inertia_y_axis" params="m r l">
    <inertial>
      <origin xyz="0 0 0" rpy="0 0 0"/>
      <mass value="${m}"/>
      <inertia
        ixx="${m / 12.0 * (3.0 * r * r + l * l)}"
        ixy="0.0"
        ixz="0.0"
        iyy="${0.5 * m * r * r}"
        iyz="0.0"
        izz="${m / 12.0 * (3.0 * r * r + l * l)}"/>
    </inertial>
  </xacro:macro>

  <!-- small steering cylinder axis is Z -->
  <xacro:macro name="cylinder_inertia_z_axis" params="m r l">
    <inertial>
      <origin xyz="0 0 0" rpy="0 0 0"/>
      <mass value="${m}"/>
      <inertia
        ixx="${m / 12.0 * (3.0 * r * r + l * l)}"
        ixy="0.0"
        ixz="0.0"
        iyy="${m / 12.0 * (3.0 * r * r + l * l)}"
        iyz="0.0"
        izz="${0.5 * m * r * r}"/>
    </inertial>
  </xacro:macro>

  <!-- ===================== -->
  <!-- Base Link -->
  <!-- ===================== -->
  <link name="base_link">
    <visual>
      <origin xyz="0 0 ${base_height / 2.0}" rpy="0 0 0"/>
      <geometry>
        <box size="${base_length} ${base_width} ${base_height}"/>
      </geometry>
      <material name="blue"/>
    </visual>

    <collision>
      <origin xyz="0 0 ${base_height / 2.0}" rpy="0 0 0"/>
      <geometry>
        <box size="${base_length} ${base_width} ${base_height}"/>
      </geometry>
    </collision>

    <xacro:box_inertia
      m="${base_mass}"
      x="${base_length}"
      y="${base_width}"
      z="${base_height}"/>
  </link>

  <!-- ===================== -->
  <!-- Front Steering Link Macro -->
  <!-- ===================== -->
  <xacro:macro name="front_steer_module" params="side y">
    <link name="front_${side}_steer_link">
      <visual>
        <origin xyz="0 0 0" rpy="0 0 0"/>
        <geometry>
          <cylinder radius="${steer_link_radius}" length="${steer_link_length}"/>
        </geometry>
        <material name="red"/>
      </visual>

      <collision>
        <origin xyz="0 0 0" rpy="0 0 0"/>
        <geometry>
          <cylinder radius="${steer_link_radius}" length="${steer_link_length}"/>
        </geometry>
      </collision>

      <xacro:cylinder_inertia_z_axis
        m="${steer_link_mass}"
        r="${steer_link_radius}"
        l="${steer_link_length}"/>
    </link>

    <joint name="front_${side}_steer_joint" type="revolute">
      <parent link="base_link"/>
      <child link="front_${side}_steer_link"/>
      <origin xyz="${front_x} ${y} ${wheel_radius}" rpy="0 0 0"/>
      <axis xyz="0 0 1"/>
      <limit lower="-0.6" upper="0.6" effort="10.0" velocity="2.0"/>
    </joint>

    <link name="front_${side}_wheel_link">
      <visual>
        <origin xyz="0 0 0" rpy="1.5708 0 0"/>
        <geometry>
          <cylinder radius="${wheel_radius}" length="${wheel_width}"/>
        </geometry>
        <material name="black"/>
      </visual>

      <collision>
        <origin xyz="0 0 0" rpy="1.5708 0 0"/>
        <geometry>
          <cylinder radius="${wheel_radius}" length="${wheel_width}"/>
        </geometry>
      </collision>

      <xacro:wheel_inertia_y_axis
        m="${wheel_mass}"
        r="${wheel_radius}"
        l="${wheel_width}"/>
    </link>

    <joint name="front_${side}_wheel_joint" type="continuous">
      <parent link="front_${side}_steer_link"/>
      <child link="front_${side}_wheel_link"/>
      <origin xyz="0 0 0" rpy="0 0 0"/>
      <axis xyz="0 1 0"/>
    </joint>
  </xacro:macro>

  <!-- ===================== -->
  <!-- Rear Wheel Macro -->
  <!-- ===================== -->
  <xacro:macro name="rear_wheel" params="side y">
    <link name="rear_${side}_wheel_link">
      <visual>
        <origin xyz="0 0 0" rpy="1.5708 0 0"/>
        <geometry>
          <cylinder radius="${wheel_radius}" length="${wheel_width}"/>
        </geometry>
        <material name="black"/>
      </visual>

      <collision>
        <origin xyz="0 0 0" rpy="1.5708 0 0"/>
        <geometry>
          <cylinder radius="${wheel_radius}" length="${wheel_width}"/>
        </geometry>
      </collision>

      <xacro:wheel_inertia_y_axis
        m="${wheel_mass}"
        r="${wheel_radius}"
        l="${wheel_width}"/>
    </link>

    <joint name="rear_${side}_wheel_joint" type="continuous">
      <parent link="base_link"/>
      <child link="rear_${side}_wheel_link"/>
      <origin xyz="${rear_x} ${y} ${wheel_radius}" rpy="0 0 0"/>
      <axis xyz="0 1 0"/>
    </joint>
  </xacro:macro>

  <!-- ===================== -->
  <!-- Instantiate Wheels -->
  <!-- ===================== -->
  <xacro:front_steer_module side="left"  y="${left_y}"/>
  <xacro:front_steer_module side="right" y="${right_y}"/>

  <xacro:rear_wheel side="left"  y="${left_y}"/>
  <xacro:rear_wheel side="right" y="${right_y}"/>

  <!-- ===================== -->
  <!-- Laser Placeholder -->
  <!-- ===================== -->
  <link name="laser_link">
    <visual>
      <origin xyz="0 0 0" rpy="0 0 0"/>
      <geometry>
        <cylinder radius="0.04" length="0.04"/>
      </geometry>
      <material name="gray"/>
    </visual>

    <collision>
      <origin xyz="0 0 0" rpy="0 0 0"/>
      <geometry>
        <cylinder radius="0.04" length="0.04"/>
      </geometry>
    </collision>

    <xacro:cylinder_inertia_z_axis m="0.1" r="0.04" l="0.04"/>
  </link>

  <joint name="laser_joint" type="fixed">
    <parent link="base_link"/>
    <child link="laser_link"/>
    <origin xyz="0.18 0 0.18" rpy="0 0 0"/>
  </joint>

  <!-- ===================== -->
  <!-- Gazebo Materials -->
  <!-- ===================== -->
  <gazebo reference="base_link">
    <material>Gazebo/Blue</material>
  </gazebo>

  <gazebo reference="front_left_steer_link">
    <material>Gazebo/Red</material>
  </gazebo>

  <gazebo reference="front_right_steer_link">
    <material>Gazebo/Red</material>
  </gazebo>

  <gazebo reference="front_left_wheel_link">
    <material>Gazebo/Black</material>
  </gazebo>

  <gazebo reference="front_right_wheel_link">
    <material>Gazebo/Black</material>
  </gazebo>

  <gazebo reference="rear_left_wheel_link">
    <material>Gazebo/Black</material>
  </gazebo>

  <gazebo reference="rear_right_wheel_link">
    <material>Gazebo/Black</material>
  </gazebo>

  <gazebo reference="laser_link">
    <material>Gazebo/Grey</material>
  </gazebo>

  



  <!-- ===================== -->
  <!-- ros2_control for Gazebo -->
  <!-- ===================== -->
  <xacro:if value="$(arg use_ros2_control)">

    <ros2_control name="GazeboSystem" type="system">
      <hardware>
        <plugin>gazebo_ros2_control/GazeboSystem</plugin>
      </hardware>

      <joint name="front_left_steer_joint">
        <command_interface name="position">
          <param name="min">-0.6</param>
          <param name="max">0.6</param>
        </command_interface>
        <state_interface name="position"/>
        <state_interface name="velocity"/>
      </joint>

      <joint name="front_right_steer_joint">
        <command_interface name="position">
          <param name="min">-0.6</param>
          <param name="max">0.6</param>
        </command_interface>
        <state_interface name="position"/>
        <state_interface name="velocity"/>
      </joint>

      <joint name="front_left_wheel_joint">
        <state_interface name="position"/>
        <state_interface name="velocity"/>
      </joint>

      <joint name="front_right_wheel_joint">
        <state_interface name="position"/>
        <state_interface name="velocity"/>
      </joint>

      <joint name="rear_left_wheel_joint">
        <command_interface name="velocity">
          <param name="min">-20.0</param>
          <param name="max">20.0</param>
        </command_interface>
        <state_interface name="position"/>
        <state_interface name="velocity"/>
      </joint>

      <joint name="rear_right_wheel_joint">
        <command_interface name="velocity">
          <param name="min">-20.0</param>
          <param name="max">20.0</param>
        </command_interface>
        <state_interface name="position"/>
        <state_interface name="velocity"/>
      </joint>
    </ros2_control>

    <gazebo>
      <plugin name="gazebo_ros2_control" filename="libgazebo_ros2_control.so">
        <robot_param>robot_description</robot_param>
        <robot_param_node>robot_state_publisher</robot_param_node>
        <parameters>$(arg control_config)</parameters>
      </plugin>
    </gazebo>

  </xacro:if>

</robot>